DEB [20111128-17:11:01.456] thr=1   paramiko.transport: starting thread (server mode): 0x8b556ecL
INF [20111128-17:11:01.456] thr=1   paramiko.transport: Connected (version 2.0, client paramiko_1.7.7.1)
DEB [20111128-17:11:01.457] thr=1   paramiko.transport: kex algos:['diffie-hellman-group1-sha1', 'diffie-hellman-group-exchange-sha1'] server key:['ssh-rsa', 'ssh-dss'] client encrypt:['aes128-ctr', 'aes256-ctr', 'aes128-cbc', 'blowfish-cbc', 'aes256-cbc', '3des-cbc', 'arcfour128', 'arcfour256'] server encrypt:['aes128-ctr', 'aes256-ctr', 'aes128-cbc', 'blowfish-cbc', 'aes256-cbc', '3des-cbc', 'arcfour128', 'arcfour256'] client mac:['hmac-sha1', 'hmac-md5', 'hmac-sha1-96', 'hmac-md5-96'] server mac:['hmac-sha1', 'hmac-md5', 'hmac-sha1-96', 'hmac-md5-96'] client compress:['none'] server compress:['none'] client lang:[''] server lang:[''] kex follows?False
DEB [20111128-17:11:01.458] thr=1   paramiko.transport: Ciphers agreed: local=aes128-ctr, remote=aes128-ctr
DEB [20111128-17:11:01.458] thr=1   paramiko.transport: using kex diffie-hellman-group1-sha1; server key type ssh-rsa; cipher: local aes128-ctr, remote aes128-ctr; mac: local hmac-sha1, remote hmac-sha1; compression: local none, remote none
DEB [20111128-17:11:01.611] thr=1   paramiko.transport: Switch to new keys ...
DEB [20111128-17:11:01.690] thr=1   paramiko.transport: Auth request (type=publickey) service=ssh-connection, username=foo
ERR [20111128-17:11:01.748] thr=1   paramiko.transport: Unknown exception: No row was found for one()
ERR [20111128-17:11:01.779] thr=1   paramiko.transport: Traceback (most recent call last):
ERR [20111128-17:11:01.779] thr=1   paramiko.transport:   File "/usr/lib/python2.7/dist-packages/paramiko/transport.py", line 1559, in run
ERR [20111128-17:11:01.780] thr=1   paramiko.transport:     self.auth_handler._handler_table[ptype](self.auth_handler, m)
ERR [20111128-17:11:01.780] thr=1   paramiko.transport:   File "/usr/lib/python2.7/dist-packages/paramiko/auth_handler.py", line 321, in _parse_userauth_request
ERR [20111128-17:11:01.780] thr=1   paramiko.transport:     result = self.transport.server_object.check_auth_publickey(username, key)
ERR [20111128-17:11:01.780] thr=1   paramiko.transport:   File "./server.py", line 71, in check_auth_publickey
ERR [20111128-17:11:01.780] thr=1   paramiko.transport:     user = Session._userRequest.getUserByName(username)
ERR [20111128-17:11:01.780] thr=1   paramiko.transport:   File "/home/keld/tmp/eip/git/4am-core/database/request/userRequest.py", line 22, in getUserByName
ERR [20111128-17:11:01.781] thr=1   paramiko.transport:     ret = self._session.query(user.User).filter_by(firstname=name).one()
ERR [20111128-17:11:01.781] thr=1   paramiko.transport:   File "/usr/local/lib/python2.7/dist-packages/SQLAlchemy-0.7.4dev-py2.7.egg/sqlalchemy/orm/query.py", line 1995, in one
ERR [20111128-17:11:01.781] thr=1   paramiko.transport:     raise orm_exc.NoResultFound("No row was found for one()")
ERR [20111128-17:11:01.781] thr=1   paramiko.transport: NoResultFound: No row was found for one()
ERR [20111128-17:11:01.781] thr=1   paramiko.transport: 
